Workbook

Sheet Pan
B4: WEEK 1-4 | E4: AUTUNNO 2023 | X4: SAMUELE MALAVASI
X5: S M
B6: DATA_PAN
H8: Wk 1 | L8: Wk 2 | P8: Wk 3 | T8: Wk 4
C9: Sequenza | E9: %1RM | F9: Nm | G9: Nr | H9: S | I9: R | J9: TotR | K9: Esito | L9: S | M9: R | N9: TotR | O9: Esito | P9: S | Q9: R | R9: TotR | S9: Esito | T9: S | U9: R | V9: TotR | W9: Esito
C10: GIORNO 1
E11: =IFERROR((INDEX(PanScale!$B$4:$N$13,MATCH(F11,PanScale!$B$4:$B$13,0),MATCH(G11,PanScale!$B$4:$N$4,0))),0%) | J11: =PRODUCT($F11*H11*I11) | N11: =PRODUCT($F11*L11*M11) | R11: =PRODUCT($F11*P11*Q11) | V11: =PRODUCT($F11*T11*U11)
E12: =IFERROR((INDEX(PanScale!$B$4:$N$13,MATCH(F12,PanScale!$B$4:$B$13,0),MATCH(G12,PanScale!$B$4:$N$4,0))),0%) | J12: =PRODUCT($F12*H12*I12) | N12: =PRODUCT($F12*L12*M12) | R12: =PRODUCT($F12*P12*Q12) | V12: =PRODUCT($F12*T12*U12)
E13: =IFERROR((INDEX(PanScale!$B$4:$N$13,MATCH(F13,PanScale!$B$4:$B$13,0),MATCH(G13,PanScale!$B$4:$N$4,0))),0%) | J13: =PRODUCT($F13*H13*I13) | N13: =PRODUCT($F13*L13*M13) | R13: =PRODUCT($F13*P13*Q13) | V13: =PRODUCT($F13*T13*U13)
D16: Recupero:
D17: Volume totale : | H17: =SUMPRODUCT(($F11:$F13*H11:H13)*I11:I13) | L17: =SUMPRODUCT(($F11:$F13*L11:L13)*M11:M13) | P17: =SUMPRODUCT(($F11:$F13*P11:P13)*Q11:Q13) | T17: =SUMPRODUCT(($F11:$F13*T11:T13)*U11:U13)
D18: Intensità totale : | H18: =IFERROR(SUMPRODUCT($E11:$E13,J11:J13)/SUM(J11:J13),"") | L18: =IFERROR(SUMPRODUCT($E11:$E13,N11:N13)/SUM(N11:N13),"") | P18: =IFERROR(SUMPRODUCT($E11:$E13,R11:R13)/SUM(R11:R13),"") | T18: =IFERROR(SUMPRODUCT($E11:$E13,V11:V13)/SUM(V11:V13),"")
C20: Nella colonna "Sequenza" troverai l'ordine con cui dovrai spostare le mani sul pan gullich, se è indicata solo la sequenza con una mano dovrai farla anche con l'altra mano ( una ripetizione in questo caso sono due salite, una di dx e una di sx). Cerca di rimanere il più in tenuta possibile con il corpo senza oscillare lateralmente e senza ruotare troppo le spalle a destra e sinistra.
T21: 45447
B28: WEEK 5-8 | E28: =#REF! | F28: STAGIONE ANNO | M28: =$X$4
T29: =$X$5
E30: =$B$6
H32: Wk 5 | L32: Wk 6 | P32: Wk 7 | T32: Wk 8
C33: Sequenza | E33: %1RM | F33: Nm | G33: Nr | H33: S | I33: R | J33: TotR | L33: S | M33: R | N33: TotR | P33: S | Q33: R | R33: TotR | T33: S | U33: R | V33: TotR
C34: GIORNO 1
E35: =IFERROR((INDEX(PanScale!$B$4:$N$13,MATCH(F35,PanScale!$B$4:$B$13,0),MATCH(G35,PanScale!$B$4:$N$4,0))),0%) | J35: =PRODUCT($F35*H35*I35) | N35: =PRODUCT($F35*L35*M35) | R35: =PRODUCT($F35*P35*Q35) | V35: =PRODUCT($F35*T35*U35)
E36: =IFERROR((INDEX(PanScale!$B$4:$N$13,MATCH(F36,PanScale!$B$4:$B$13,0),MATCH(G36,PanScale!$B$4:$N$4,0))),0%) | J36: =PRODUCT($F36*H36*I36) | N36: =PRODUCT($F36*L36*M36) | R36: =PRODUCT($F36*P36*Q36) | V36: =PRODUCT($F36*T36*U36)
E37: =IFERROR((INDEX(PanScale!$B$4:$N$13,MATCH(F37,PanScale!$B$4:$B$13,0),MATCH(G37,PanScale!$B$4:$N$4,0))),0%) | J37: =PRODUCT($F37*H37*I37) | N37: =PRODUCT($F37*L37*M37) | R37: =PRODUCT($F37*P37*Q37) | V37: =PRODUCT($F37*T37*U37)
D39: Recupero:
D40: Volume totale : | H40: =SUMPRODUCT(($F35:$F37*H35:H37)*I35:I37) | L40: =SUMPRODUCT(($F35:$F37*L35:L37)*M35:M37) | P40: =SUMPRODUCT(($F35:$F37*P35:P37)*Q35:Q37) | T40: =SUMPRODUCT(($F35:$F37*T35:T37)*U35:U37)
D41: Intensità totale : | H41: =IFERROR(SUMPRODUCT($E35:$E37,J35:J37)/SUM(J35:J37),"") | L41: =IFERROR(SUMPRODUCT($E35:$E37,N35:N37)/SUM(N35:N37),"") | P41: =IFERROR(SUMPRODUCT($E35:$E37,R35:R37)/SUM(R35:R37),"") | T41: =IFERROR(SUMPRODUCT($E35:$E37,V35:V37)/SUM(V35:V37),"")
C43: Nella colonna "Sequenza" troverai l'ordine con cui dovrai spostare le mani sul pan gullich, se è indicata solo la sequenza con una mano dovrai farla anche con l'altra mano ( una ripetizione in questo caso sono due salite, una di dx e una di sx). Cerca di rimanere il più in tenuta possibile con il corpo senza oscillare lateralmente e senza ruotare troppo le spalle a destra e sinistra.
T44: =$T$21+28
B55: WEEK 9-12 | E55: =#REF! | M55: =$X$4
T56: =$T$29
E57: =$E$30
H59: Wk 9 | L59: Wk 10 | P59: Wk 11 | T59: Wk 12
C60: Sequenza | E60: %1RM | F60: Nm | G60: Nr | H60: S | I60: R | J60: TotR | K60: Esito | L60: S | M60: R | N60: TotR | O60: Esito | P60: S | Q60: R | R60: TotR | S60: Esito | T60: S | U60: R | V60: TotR | W60: Esito
C61: GIORNO 1
E62: =IFERROR((INDEX(PanScale!$B$4:$N$13,MATCH(F62,PanScale!$B$4:$B$13,0),MATCH(G62,PanScale!$B$4:$N$4,0))),0%) | J62: =PRODUCT($F62*H62*I62) | N62: =PRODUCT($F62*L62*M62) | R62: =PRODUCT($F62*P62*Q62) | V62: =PRODUCT($F62*T62*U62)
E63: =IFERROR((INDEX(PanScale!$B$4:$N$13,MATCH(F63,PanScale!$B$4:$B$13,0),MATCH(G63,PanScale!$B$4:$N$4,0))),0%) | J63: =PRODUCT($F63*H63*I63) | N63: =PRODUCT($F63*L63*M63) | R63: =PRODUCT($F63*P63*Q63) | V63: =PRODUCT($F63*T63*U63)
E64: =IFERROR((INDEX(PanScale!$B$4:$N$13,MATCH(F64,PanScale!$B$4:$B$13,0),MATCH(G64,PanScale!$B$4:$N$4,0))),0%) | J64: =PRODUCT($F64*H64*I64) | N64: =PRODUCT($F64*L64*M64) | R64: =PRODUCT($F64*P64*Q64) | V64: =PRODUCT($F64*T64*U64)
D66: Recupero:
D67: Volume totale : | H67: =SUMPRODUCT(($F62:$F64*H62:H64)*I62:I64) | L67: =SUMPRODUCT(($F62:$F64*L62:L64)*M62:M64) | P67: =SUMPRODUCT(($F62:$F64*P62:P64)*Q62:Q64) | T67: =SUMPRODUCT(($F62:$F64*T62:T64)*U62:U64)
D68: Intensità totale : | H68: =IFERROR(SUMPRODUCT($E62:$E64,J62:J64)/SUM(J62:J64),"") | L68: =IFERROR(SUMPRODUCT($E62:$E64,N62:N64)/SUM(N62:N64),"") | P68: =IFERROR(SUMPRODUCT($E62:$E64,R62:R64)/SUM(R62:R64),"") | T68: =IFERROR(SUMPRODUCT($E62:$E64,V62:V64)/SUM(V62:V64),"")
...
