Workbook

Sheet Week 5-8
B4: WEEK 5-8 | N4: ='Week 1-4'!$N$4 | AF4: ='Week 1-4'!$AF$4
AD5: ='Week 1-4'!$AF$5
N6: ='Week 1-4'!$N$6
D8: Week 5, Day 1 | K8: Week 6, Day 1 | R8: Week 7, Day 1 | Y8: Week 8, Day 1
C9: Exercise | D9: Set | E9: Rep | F9: Load | G9: Note | H9: % | I9: Tonnage | J9: Rest | K9: Set | L9: Rep | M9: Load | N9: Note | O9: % | P9: Tonnage | Q9: Rest | R9: Set | S9: Rep | T9: Load | U9: Note | V9: % | W9: Tonnage | X9: Rest | Y9: Set | Z9: Rep | AA9: Load | AB9: Note | AC9: % | AD9: Tonnage | AE9: Rest
I10: =D10*E10*F10 | P10: =K10*L10*M10 | W10: =R10*S10*T10 | AD10: =Y10*Z10*AA10
I11: =D11*E11*F11 | P11: =K11*L11*M11 | W11: =R11*S11*T11 | AD11: =Y11*Z11*AA11
I12: =D12*E12*F12 | P12: =K12*L12*M12 | W12: =R12*S12*T12 | AD12: =Y12*Z12*AA12
I13: =D13*E13*F13 | P13: =K13*L13*M13 | W13: =R13*S13*T13 | AD13: =Y13*Z13*AA13
I14: =D14*E14*F14 | P14: =K14*L14*M14 | W14: =R14*S14*T14 | AD14: =Y14*Z14*AA14
I15: =D15*E15*F15 | P15: =K15*L15*M15 | W15: =R15*S15*T15 | AD15: =Y15*Z15*AA15
I16: =D16*E16*F16 | P16: =K16*L16*M16 | W16: =R16*S16*T16 | AD16: =Y16*Z16*AA16
I17: =D17*E17*F17 | P17: =K17*L17*M17 | W17: =R17*S17*T17 | AD17: =Y17*Z17*AA17
I18: =D18*E18*F18 | P18: =K18*L18*M18 | W18: =R18*S18*T18 | AD18: =Y18*Z18*AA18
I19: =D19*E19*F19 | P19: =K19*L19*M19 | W19: =R19*S19*T19 | AD19: =Y19*Z19*AA19
D21: Day 2 | K21: Day 2 | R21: Day 2 | Y21: Day 2
C22: Exercise | D22: Set | E22: Rep | F22: Load | G22: Note | H22: % | I22: Tonnage | J22: Rest | K22: Set | L22: Rep | M22: Load | N22: Note | O22: % | P22: Tonnage | Q22: Rest | R22: Set | S22: Rep | T22: Load | U22: Note | V22: % | W22: Tonnage | X22: Rest | Y22: Set | Z22: Rep | AA22: Load | AB22: Note | AC22: % | AD22: Tonnage | AE22: Rest
I23: =D23*E23*F23 | P23: =K23*L23*M23 | W23: =R23*S23*T23 | AD23: =Y23*Z23*AA23
I24: =D24*E24*F24 | P24: =K24*L24*M24 | W24: =R24*S24*T24 | AD24: =Y24*Z24*AA24
I25: =D25*E25*F25 | P25: =K25*L25*M25 | W25: =R25*S25*T25 | AD25: =Y25*Z25*AA25
I26: =D26*E26*F26 | P26: =K26*L26*M26 | W26: =R26*S26*T26 | AD26: =Y26*Z26*AA26
I27: =D27*E27*F27 | P27: =K27*L27*M27 | W27: =R27*S27*T27 | AD27: =Y27*Z27*AA27
I28: =D28*E28*F28 | P28: =K28*L28*M28 | W28: =R28*S28*T28 | AD28: =Y28*Z28*AA28
I29: =D29*E29*F29 | P29: =K29*L29*M29 | W29: =R29*S29*T29 | AD29: =Y29*Z29*AA29
I30: =D30*E30*F30 | P30: =K30*L30*M30 | W30: =R30*S30*T30 | AD30: =Y30*Z30*AA30
I31: =D31*E31*F31 | P31: =K31*L31*M31 | W31: =R31*S31*T31 | AD31: =Y31*Z31*AA31
D33: Day 3 | K33: Day 3 | R33: Day 3 | Y33: Day 3
C34: Exercise | D34: Set | E34: Rep | F34: Load | G34: Note | H34: % | I34: Tonnage | J34: Rest | K34: Set | L34: Rep | M34: Load | N34: Note | O34: % | P34: Tonnage | Q34: Rest | R34: Set | S34: Rep | T34: Load | U34: Note | V34: % | W34: Tonnage | X34: Rest | Y34: Set | Z34: Rep | AA34: Load | AB34: Note | AC34: % | AD34: Tonnage | AE34: Rest
I35: =D35*E35*F35 | P35: =K35*L35*M35 | W35: =R35*S35*T35 | AD35: =Y35*Z35*AA35
I36: =D36*E36*F36 | P36: =K36*L36*M36 | W36: =R36*S36*T36 | AD36: =Y36*Z36*AA36
I37: =D37*E37*F37 | P37: =K37*L37*M37 | W37: =R37*S37*T37 | AD37: =Y37*Z37*AA37
I38: =D38*E38*F38 | P38: =K38*L38*M38 | W38: =R38*S38*T38 | AD38: =Y38*Z38*AA38
I39: =D39*E39*F39 | P39: =K39*L39*M39 | W39: =R39*S39*T39 | AD39: =Y39*Z39*AA39
I40: =D40*E40*F40 | P40: =K40*L40*M40 | W40: =R40*S40*T40 | AD40: =Y40*Z40*AA40
I41: =D41*E41*F41 | P41: =K41*L41*M41 | W41: =R41*S41*T41 | AD41: =Y41*Z41*AA41
I42: =D42*E42*F42 | P42: =K42*L42*M42 | W42: =R42*S42*T42 | AD42: =Y42*Z42*AA42
I43: =D43*E43*F43 | P43: =K43*L43*M43 | W43: =R43*S43*T43 | AD43: =Y43*Z43*AA43
I44: =D44*E44*F44 | P44: =K44*L44*M44 | W44: =R44*S44*T44 | AD44: =Y44*Z44*AA44
D46: Day 4 | K46: Day 4 | R46: Day 4 | Y46: Day 4
C47: Exercise | D47: Set | E47: Rep | F47: Load | G47: Note | H47: % | I47: Tonnage | J47: Rest | K47: Set | L47: Rep | M47: Load | N47: Note | O47: % | P47: Tonnage | Q47: Rest | R47: Set | S47: Rep | T47: Load | U47: Note | V47: % | W47: Tonnage | X47: Rest | Y47: Set | Z47: Rep | AA47: Load | AB47: Note | AC47: % | AD47: Tonnage | AE47: Rest
...
